Workbook

Sheet Dashboard
A1: STUDENT PAYMENT & BOOK DISTRIBUTION DASHBOARD | AA1: Class | AB1: Total Students | AC1: Paid | AD1: Not Paid | AE1: Collection | AG1: Date | AH1: Collection | AJ1: Month | AK1: Collection | AL1: Transactions
AA2: 10-A | AB2: 38 | AC2: 1 | AD2: 37 | AE2: 1500 | AG2: 46209 | AH2: 1000 | AJ2: July | AK2: 52000 | AL2: 104
A3: BOOKS ISSUED | F3: TOTAL STUDENTS | AA3: 10-B | AB3: 9 | AC3: 0 | AD3: 9 | AE3: 0 | AG3: 46210 | AH3: 500 | AJ3: August | AK3: 340000 | AL3: 674
A4: =COUNTA('ALL STUDENTS'!A:A)-1 -> 2601 | F4: =COUNTA('ALL STUDENTS'!A:A)-1 -> 2601 | AA4: 10-C | AB4: 21 | AC4: 1 | AD4: 20 | AE4: 500 | AG4: 46225 | AH4: 2500 | AJ4: September | AK4: 264000 | AL4: 522
A5: NOT FOUND | AA5: 10-D | AB5: 25 | AC5: 1 | AD5: 24 | AE5: 1000 | AG5: 46226 | AH5: 2000
A6: =COUNTIF('Raw Entries'!I:I, "NOT FOUND") -> 68 | D6: STUDENTS PAID | H6: STUDENTS UNPAID | AA6: 10-E | AB6: 12 | AC6: 0 | AD6: 12 | AE6: 0 | AG6: 46227 | AH6: 2000
A7: TRANSACTIONS | D7: =COUNTA('Classwise Summary'!B:B)-1 -> 696 | H7: =F4-B13 -> 1906 | AA7: 10-F | AB7: 6 | AC7: 0 | AD7: 6 | AE7: 0 | AG7: 46228 | AH7: 5500
A8: =COUNTA('Raw Entries'!G:G)-1 -> 1445 | AA8: 1-A | AB8: 36 | AC8: 13 | AD8: 23 | AE8: 13000 | AG8: 46229 | AH8: 4000
A9: TOTAL COLLECTION | AA9: 1-B | AB9: 38 | AC9: 7 | AD9: 31 | AE9: 7500 | AG9: 46230 | AH9: 5500
A10: =SUM('Classwise Summary'!E2:E894) -> 661000 | AA10: 1-C | AB10: 38 | AC10: 14 | AD10: 24 | AE10: 15500 | AG10: 46231 | AH10: 5500
AA11: 1-D | AB11: 38 | AC11: 12 | AD11: 26 | AE11: 9000 | AG11: 46232 | AH11: 7500
B12: 1st Installment | AA12: 1-E | AB12: 38 | AC12: 11 | AD12: 27 | AE12: 10000 | AG12: 46233 | AH12: 8000
B13: ='Classwise Summary'!G8 -> 695 | E13: 2nd Installment | AA13: 1-F | AB13: 39 | AC13: 10 | AD13: 29 | AE13: 10000 | AG13: 46234 | AH13: 8000
E14: ='Classwise Summary'!H8 -> 426 | AA14: 1-G | AB14: 39 | AC14: 13 | AD14: 26 | AE14: 13500 | AG14: 46235 | AH14: 59500
H15: 3rd Installment | AA15: 1-H | AB15: 38 | AC15: 12 | AD15: 26 | AE15: 14000 | AG15: 46236 | AH15: 500
H16: ='Classwise Summary'!I8 -> 269 | AA16: 1-I | AB16: 37 | AC16: 10 | AD16: 27 | AE16: 9000 | AG16: 46237 | AH16: 27000
AA17: 2-A | AB17: 40 | AC17: 12 | AD17: 28 | AE17: 14000 | AG17: 46238 | AH17: 14500
A18: TOTAL COLLECTION | K18: total | AA18: 2-B | AB18: 40 | AC18: 5 | AD18: 35 | AE18: 4000 | AG18: 46239 | AH18: 24500
AA19: 2-C | AB19: 40 | AC19: 12 | AD19: 28 | AE19: 10500 | AG19: 46240 | AH19: 35000
A20: =A10 -> 661000 | AA20: 2-D | AB20: 40 | AC20: 11 | AD20: 29 | AE20: 10000 | AG20: 46241 | AH20: 14000
AA21: 2-E | AB21: 40 | AC21: 10 | AD21: 30 | AE21: 8500 | AG21: 46242 | AH21: 4500
AA22: 2-F | AB22: 39 | AC22: 6 | AD22: 33 | AE22: 8000 | AG22: 46243 | AH22: 3500
AA23: 2-G | AB23: 38 | AC23: 11 | AD23: 27 | AE23: 10500 | AG23: 46244 | AH23: 1500
AA24: 2-H | AB24: 35 | AC24: 6 | AD24: 29 | AE24: 5000 | AG24: 46245 | AH24: 14000
AA25: 2-I | AB25: 35 | AC25: 7 | AD25: 28 | AE25: 6000 | AG25: 46246 | AH25: 17000
AA26: 3-A | AB26: 36 | AC26: 10 | AD26: 26 | AE26: 21000 | AG26: 46247 | AH26: 12000
AA27: 3-B | AB27: 39 | AC27: 15 | AD27: 24 | AE27: 19000 | AG27: 46248 | AH27: 8500
AA28: 3-C | AB28: 38 | AC28: 9 | AD28: 29 | AE28: 10500 | AG28: 46249 | AH28: 1000
AA29: 3-D | AB29: 38 | AC29: 9 | AD29: 29 | AE29: 11000 | AG29: 46251 | AH29: 8000
AA30: 3-E | AB30: 39 | AC30: 7 | AD30: 32 | AE30: 9500 | AG30: 46252 | AH30: 6500
AA31: 3-F | AB31: 36 | AC31: 10 | AD31: 26 | AE31: 14500 | AG31: 46253 | AH31: 7500
AA32: 3-G | AB32: 37 | AC32: 7 | AD32: 30 | AE32: 6000 | AG32: 46254 | AH32: 8500
... AA60: 7-E | AB60: 47 | AC60: 4 | AD60: 43 | AE60: 5000 | AG60: 46286 | AH60: 5000
AA61: 7-F | AB61: 30 | AC61: 4 | AD61: 26 | AE61: 3000
AA62: 7-G | AB62: 16 | AC62: 5 | AD62: 11 | AE62: 4500
AA63: 8-A | AB63: 34 | AC63: 6 | AD63: 28 | AE63: 6000
AA64: 8-B | AB64: 34 | AC64: 6 | AD64: 28 | AE64: 5500
AA65: 8-C | AB65: 34 | AC65: 13 | AD65: 21 | AE65: 10500
AA66: 8-D | AB66: 31 | AC66: 6 | AD66: 25 | AE66: 4500
AA67: 8-E | AB67: 32 | AC67: 4 | AD67: 28 | AE67: 3000
...

Sheet Classwise Summary
A1: Sr No | B1: Class | C1: Unique Student Name | D1: Total Count | E1: PAID
A2: 1 | B2: UKG-A | C2: Alfa Korah | D2: =COUNTIFS('Raw Entries'!B:B,ClasswiseUniqueStudents7[[#This Row],[Unique Student Name]],'Raw Entries'!C:C,ClasswiseUniqueStudents7[[#This Row],[Class]]) -> 2 | E2: =ClasswiseUniqueStudents7[[#This Row],[Total Count]]*500 -> 1000
A3: 2 | B3: UKG-A | C3: ANIKA THAKUR | D3: =COUNTIFS('Raw Entries'!B:B,ClasswiseUniqueStudents7[[#This Row],[Unique Student Name]],'Raw Entries'!C:C,ClasswiseUniqueStudents7[[#This Row],[Class]]) -> 1 | E3: =ClasswiseUniqueStudents7[[#This Row],[Total Count]]*500 -> 500 | G3: TOTAL COLLECTION | J3: =SUM(E:E) -> 661000
A4: 3 | B4: UKG-A | C4: RITIKA | D4: =COUNTIFS('Raw Entries'!B:B,ClasswiseUniqueStudents7[[#This Row],[Unique Student Name]],'Raw Entries'!C:C,ClasswiseUniqueStudents7[[#This Row],[Class]]) -> 3 | E4: =ClasswiseUniqueStudents7[[#This Row],[Total Count]]*500 -> 1500
A5: 4 | B5: UKG-A | C5: ARNAV DUBEY | D5: =COUNTIFS('Raw Entries'!B:B,ClasswiseUniqueStudents7[[#This Row],[Unique Student Name]],'Raw Entries'!C:C,ClasswiseUniqueStudents7[[#This Row],[Class]]) -> 1 | E5: =ClasswiseUniqueStudents7[[#This Row],[Total Count]]*500 -> 500
A6: 5 | B6: UKG-A | C6: AROHI SAHU | D6: =COUNTIFS('Raw Entries'!B:B,ClasswiseUniqueStudents7[[#This Row],[Unique Student Name]],'Raw Entries'!C:C,ClasswiseUniqueStudents7[[#This Row],[Class]]) -> 3 | E6: =ClasswiseUniqueStudents7[[#This Row],[Total Count]]*500 -> 1500 | G6: 1st installment | H6: 2nd installment | I6: 3rd installment
A7: 6 | B7: UKG-A | C7: DIVIKA SINGH | D7: =COUNTIFS('Raw Entries'!B:B,ClasswiseUniqueStudents7[[#This Row],[Unique Student Name]],'Raw Entries'!C:C,ClasswiseUniqueStudents7[[#This Row],[Class]]) -> 3 | E7: =ClasswiseUniqueStudents7[[#This Row],[Total Count]]*500 -> 1500
A8: 7 | B8: UKG-A | C8: VIVAN SINGH RAJBHOPA | D8: =COUNTIFS('Raw Entries'!B:B,ClasswiseUniqueStudents7[[#This Row],[Unique Student Name]],'Raw Entries'!C:C,ClasswiseUniqueStudents7[[#This Row],[Class]]) -> 2 | E8: =ClasswiseUniqueStudents7[[#This Row],[Total Count]]*500 -> 1000 | G8: =COUNTIF(D:D,1)+COUNTIF(D:D,2)+COUNTIF(D:D,3) -> 695 | H8: =COUNTIF(D:D,1)+COUNTIF(D:D,2) -> 426 | I8: =COUNTIF(D:D,3) -> 269
A9: 8 | B9: UKG-A | C9: ERISHA LAKRA | D9: =COUNTIFS('Raw Entries'!B:B,ClasswiseUniqueStudents7[[#This Row],[Unique Student Name]],'Raw Entries'!C:C,ClasswiseUniqueStudents7[[#This Row],[Class]]) -> 1 | E9: =ClasswiseUniqueStudents7[[#This Row],[Total Count]]*500 -> 500
A10: 9 | B10: UKG-A | C10: DAKSH LUDHELE | D10: =COUNTIFS('Raw Entries'!B:B,ClasswiseUniqueStudents7[[#This Row],[Unique Student Name]],'Raw Entries'!C:C,ClasswiseUniqueStudents7[[#This Row],[Class]]) -> 3 | E10: =ClasswiseUniqueStudents7[[#This Row],[Total Count]]*500 -> 1500
A11: 10 | B11: UKG-A | C11: RACHIT KUMAR | D11: =COUNTIFS('Raw Entries'!B:B,ClasswiseUniqueStudents7[[#This Row],[Unique Student Name]],'Raw Entries'!C:C,ClasswiseUniqueStudents7[[#This Row],[Class]]) -> 1 | E11: =ClasswiseUniqueStudents7[[#This Row],[Total Count]]*500 -> 500
A12: 11 | B12: UKG-A | C12: ISHAAN GAIKWAD | D12: =COUNTIFS('Raw Entries'!B:B,ClasswiseUniqueStudents7[[#This Row],[Unique Student Name]],'Raw Entries'!C:C,ClasswiseUniqueStudents7[[#This Row],[Class]]) -> 3 | E12: =ClasswiseUniqueStudents7[[#This Row],[Total Count]]*500 -> 1500
A13: 12 | B13: UKG-A | C13: DEVANSH MEHRA | D13: =COUNTIFS('Raw Entries'!B:B,ClasswiseUniqueStudents7[[#This Row],[Unique Student Name]],'Raw Entries'!C:C,ClasswiseUniqueStudents7[[#This Row],[Class]]) -> 1 | E13: =ClasswiseUniqueStudents7[[#This Row],[Total Count]]*500 -> 500
A14: 13 | B14: UKG-A | C14: AADHVIK BAHUMIK | D14: =COUNTIFS('Raw Entries'!B:B,ClasswiseUniqueStudents7[[#This Row],[Unique Student Name]],'Raw Entries'!C:C,ClasswiseUniqueStudents7[[#This Row],[Class]]) -> 3 | E14: =ClasswiseUniqueStudents7[[#This Row],[Total Count]]*500 -> 1500
A15: 14 | B15: UKG-A | C15: RUDRA PRATAP YADAV | D15: =COUNTIFS('Raw Entries'!B:B,ClasswiseUniqueStudents7[[#This Row],[Unique Student Name]],'Raw Entries'!C:C,ClasswiseUniqueStudents7[[#This Row],[Class]]) -> 1 | E15: =ClasswiseUniqueStudents7[[#This Row],[Total Count]]*500 -> 500
A16: 15 | B16: UKG-A | C16: RIYANSH SAHU | D16: =COUNTIFS('Raw Entries'!B:B,ClasswiseUniqueStudents7[[#This Row],[Unique Student Name]],'Raw Entries'!C:C,ClasswiseUniqueStudents7[[#This Row],[Class]]) -> 1 | E16: =ClasswiseUniqueStudents7[[#This Row],[Total Count]]*500 -> 500
A17: 16 | B17: UKG-B | C17: AVIKA GUPTA | D17: =COUNTIFS('Raw Entries'!B:B,ClasswiseUniqueStudents7[[#This Row],[Unique Student Name]],'Raw Entries'!C:C,ClasswiseUniqueStudents7[[#This Row],[Class]]) -> 3 | E17: =ClasswiseUniqueStudents7[[#This Row],[Total Count]]*500 -> 1500
A18: 17 | B18: UKG-B | C18: PAKHI TEKAM | D18: =COUNTIFS('Raw Entries'!B:B,ClasswiseUniqueStudents7[[#This Row],[Unique Student Name]],'Raw Entries'!C:C,ClasswiseUniqueStudents7[[#This Row],[Class]]) -> 1 | E18: =ClasswiseUniqueStudents7[[#This Row],[Total Count]]*500 -> 500
A19: 18 | B19: UKG-B | C19: NAKSH MEENA | D19: =COUNTIFS('Raw Entries'!B:B,ClasswiseUniqueStudents7[[#This Row],[Unique Student Name]],'Raw Entries'!C:C,ClasswiseUniqueStudents7[[#This Row],[Class]]) -> 2 | E19: =ClasswiseUniqueStudents7[[#This Row],[Total Count]]*500 -> 1000
A20: 19 | B20: UKG-B | C20: VAIDIK KANOJIYA | D20: =COUNTIFS('Raw Entries'!B:B,ClasswiseUniqueStudents7[[#This Row],[Unique Student Name]],'Raw Entries'!C:C,ClasswiseUniqueStudents7[[#This Row],[Class]]) -> 3 | E20: =ClasswiseUniqueStudents7[[#This Row],[Total Count]]*500 -> 1500
... A697: 696 | B697: 2-C | C697: AYUSH KUMAR | D697: =COUNTIFS('Raw Entries'!B:B,ClasswiseUniqueStudents7[[#This Row],[Unique Student Name]],'Raw Entries'!C:C,ClasswiseUniqueStudents7[[#This Row],[Class]]) -> 1 | E697: =ClasswiseUniqueStudents7[[#This Row],[Total Count]]*500 -> 500
A698: 697 | D698: =COUNTIFS('Raw Entries'!B:B,ClasswiseUniqueStudents7[[#This Row],[Unique Student Name]],'Raw Entries'!C:C,ClasswiseUniqueStudents7[[#This Row],[Class]]) -> 0 | E698: =ClasswiseUniqueStudents7[[#This Row],[Total Count]]*500 -> 0
A699: 698 | D699: =COUNTIFS('Raw Entries'!B:B,ClasswiseUniqueStudents7[[#This Row],[Unique Student Name]],'Raw Entries'!C:C,ClasswiseUniqueStudents7[[#This Row],[Class]]) -> 0 | E699: =ClasswiseUniqueStudents7[[#This Row],[Total Count]]*500 -> 0
A700: 699 | D700: =COUNTIFS('Raw Entries'!B:B,ClasswiseUniqueStudents7[[#This Row],[Unique Student Name]],'Raw Entries'!C:C,ClasswiseUniqueStudents7[[#This Row],[Class]]) -> 0 | E700: =ClasswiseUniqueStudents7[[#This Row],[Total Count]]*500 -> 0
A701: 700 | D701: =COUNTIFS('Raw Entries'!B:B,ClasswiseUniqueStudents7[[#This Row],[Unique Student Name]],'Raw Entries'!C:C,ClasswiseUniqueStudents7[[#This Row],[Class]]) -> 0 | E701: =ClasswiseUniqueStudents7[[#This Row],[Total Count]]*500 -> 0
A702: 701 | D702: =COUNTIFS('Raw Entries'!B:B,ClasswiseUniqueStudents7[[#This Row],[Unique Student Name]],'Raw Entries'!C:C,ClasswiseUniqueStudents7[[#This Row],[Class]]) -> 0 | E702: =ClasswiseUniqueStudents7[[#This Row],[Total Count]]*500 -> 0
A703: 702 | D703: =COUNTIFS('Raw Entries'!B:B,ClasswiseUniqueStudents7[[#This Row],[Unique Student Name]],'Raw Entries'!C:C,ClasswiseUniqueStudents7[[#This Row],[Class]]) -> 0 | E703: =ClasswiseUniqueStudents7[[#This Row],[Total Count]]*500 -> 0
A704: 703 | D704: =COUNTIFS('Raw Entries'!B:B,ClasswiseUniqueStudents7[[#This Row],[Unique Student Name]],'Raw Entries'!C:C,ClasswiseUniqueStudents7[[#This Row],[Class]]) -> 0 | E704: =ClasswiseUniqueStudents7[[#This Row],[Total Count]]*500 -> 0
A705: 704 | D705: =COUNTIFS('Raw Entries'!B:B,ClasswiseUniqueStudents7[[#This Row],[Unique Student Name]],'Raw Entries'!C:C,ClasswiseUniqueStudents7[[#This Row],[Class]]) -> 0 | E705: =ClasswiseUniqueStudents7[[#This Row],[Total Count]]*500 -> 0
A706: 705 | D706: =COUNTIFS('Raw Entries'!B:B,ClasswiseUniqueStudents7[[#This Row],[Unique Student Name]],'Raw Entries'!C:C,ClasswiseUniqueStudents7[[#This Row],[Class]]) -> 0 | E706: =ClasswiseUniqueStudents7[[#This Row],[Total Count]]*500 -> 0
A707: 706 | D707: =COUNTIFS('Raw Entries'!B:B,ClasswiseUniqueStudents7[[#This Row],[Unique Student Name]],'Raw Entries'!C:C,ClasswiseUniqueStudents7[[#This Row],[Class]]) -> 0 | E707: =ClasswiseUniqueStudents7[[#This Row],[Total Count]]*500 -> 0
A708: 707 | D708: =COUNTIFS('Raw Entries'!B:B,ClasswiseUniqueStudents7[[#This Row],[Unique Student Name]],'Raw Entries'!C:C,ClasswiseUniqueStudents7[[#This Row],[Class]]) -> 0 | E708: =ClasswiseUniqueStudents7[[#This Row],[Total Count]]*500 -> 0
A709: 708 | D709: =COUNTIFS('Raw Entries'!B:B,ClasswiseUniqueStudents7[[#This Row],[Unique Student Name]],'Raw Entries'!C:C,ClasswiseUniqueStudents7[[#This Row],[Class]]) -> 0 | E709: =ClasswiseUniqueStudents7[[#This Row],[Total Count]]*500 -> 0
... A894: 893 | D894: =COUNTIFS('Raw Entries'!B:B,ClasswiseUniqueStudents7[[#This Row],[Unique Student Name]],'Raw Entries'!C:C,ClasswiseUniqueStudents7[[#This Row],[Class]]) -> 0 | E894: =ClasswiseUniqueStudents7[[#This Row],[Total Count]]*500 -> 0

Sheet Class Totals
A1: CLASS-WISE TOTALS
A2: Class | B2: Unique Students | C2: Total Paid Entries | D2: Total Fee
A3: UKG-A | B3: =COUNTIF('Classwise Summary'!B:B,A3) -> 20 | C3: =COUNTIF('Raw Entries'!C:C,ClassTotals[[#This Row],[Class]]) -> 38 | D3: =ClassTotals[[#This Row],[Total Paid Entries]]*500 -> 19000
A4: UKG-B | B4: =COUNTIF('Classwise Summary'!B:B,A4) -> 14 | C4: =COUNTIF('Raw Entries'!C:C,ClassTotals[[#This Row],[Class]]) -> 34 | D4: =ClassTotals[[#This Row],[Total Paid Entries]]*500 -> 17000
A5: UKG-C | B5: =COUNTIF('Classwise Summary'!B:B,A5) -> 22 | C5: =COUNTIF('Raw Entries'!C:C,ClassTotals[[#This Row],[Class]]) -> 52 | D5: =ClassTotals[[#This Row],[Total Paid Entries]]*500 -> 26000
A6: UKG-D | B6: =COUNTIF('Classwise Summary'!B:B,A6) -> 12 | C6: =COUNTIF('Raw Entries'!C:C,ClassTotals[[#This Row],[Class]]) -> 22 | D6: =ClassTotals[[#This Row],[Total Paid Entries]]*500 -> 11000
A7: UKG-E | B7: =COUNTIF('Classwise Summary'!B:B,A7) -> 4 | C7: =COUNTIF('Raw Entries'!C:C,ClassTotals[[#This Row],[Class]]) -> 15 | D7: =ClassTotals[[#This Row],[Total Paid Entries]]*500 -> 7500
A8: UKG-F | B8: =COUNTIF('Classwise Summary'!B:B,A8) -> 12 | C8: =COUNTIF('Raw Entries'!C:C,ClassTotals[[#This Row],[Class]]) -> 33 | D8: =ClassTotals[[#This Row],[Total Paid Entries]]*500 -> 16500
A9: 1-A | B9: =COUNTIF('Classwise Summary'!B:B,A9) -> 14 | C9: =COUNTIF('Raw Entries'!C:C,ClassTotals[[#This Row],[Class]]) -> 34 | D9: =ClassTotals[[#This Row],[Total Paid Entries]]*500 -> 17000
A10: 1-B | B10: =COUNTIF('Classwise Summary'!B:B,A10) -> 8 | C10: =COUNTIF('Raw Entries'!C:C,ClassTotals[[#This Row],[Class]]) -> 16 | D10: =ClassTotals[[#This Row],[Total Paid Entries]]*500 -> 8000
A11: 1-C | B11: =COUNTIF('Classwise Summary'!B:B,A11) -> 14 | C11: =COUNTIF('Raw Entries'!C:C,ClassTotals[[#This Row],[Class]]) -> 32 | D11: =ClassTotals[[#This Row],[Total Paid Entries]]*500 -> 16000
A12: 1-D | B12: =COUNTIF('Classwise Summary'!B:B,A12) -> 12 | C12: =COUNTIF('Raw Entries'!C:C,ClassTotals[[#This Row],[Class]]) -> 19 | D12: =ClassTotals[[#This Row],[Total Paid Entries]]*500 -> 9500
A13: 1-E | B13: =COUNTIF('Classwise Summary'!B:B,A13) -> 11 | C13: =COUNTIF('Raw Entries'!C:C,ClassTotals[[#This Row],[Class]]) -> 21 | D13: =ClassTotals[[#This Row],[Total Paid Entries]]*500 -> 10500
A14: 1-F | B14: =COUNTIF('Classwise Summary'!B:B,A14) -> 10 | C14: =COUNTIF('Raw Entries'!C:C,ClassTotals[[#This Row],[Class]]) -> 27 | D14: =ClassTotals[[#This Row],[Total Paid Entries]]*500 -> 13500
... A82: 10-F | B82: =COUNTIF('Classwise Summary'!B:B,A82) -> 0 | C82: =COUNTIF('Raw Entries'!C:C,ClassTotals[[#This Row],[Class]]) -> 0 | D82: =ClassTotals[[#This Row],[Total Paid Entries]]*500 -> 0
A84: TOTAL | B84: =SUBTOTAL(109,B3:B83) -> 696 | C84: =SUBTOTAL(109,C3:C83) -> 1444 | D84: =SUM(D3:D82) -> 722000

Sheet Raw Entries
A1: Sr No | B1: Name | C1: Class | D1: Month | E1: Fee | F1: Collection Type | G1: Receipt No | H1: Date | I1: BOOK NUMBER | J1: extra
A2: 1 | B2: ARADHYA SONI | C2: 8-D | D2: {=TEXT(Table26[[#This Row],[Date]],"MMMM")} -> July | E2: 500 | F2: Ol | G2: 1 | H2: 46230 | I2: {=IFERROR(INDEX('ALL STUDENTS'!$A:$A, MATCH(1, ('ALL STUDENTS'!$B:$B = B2) * ('ALL STUDENTS'!$C:$C = C2), 0)), "NOT FOUND")} -> 8 | J2: =IF(Table26[[#This Row],[Fee]]>500,Table26[[#This Row],[Fee]],"")
A3: 2 | B3: ARADHYA SONI | C3: 8-D | D3: {=TEXT(Table26[[#This Row],[Date]],"MMMM")} -> July | E3: 500 | F3: Ol | G3: 2 | H3: 46230 | I3: {=IFERROR(INDEX('ALL STUDENTS'!$A:$A, MATCH(1, ('ALL STUDENTS'!$B:$B = B3) * ('ALL STUDENTS'!$C:$C = C3), 0)), "NOT FOUND")} -> 8 | J3: =IF(Table26[[#This Row],[Fee]]>500,Table26[[#This Row],[Fee]],"") | L3: STUDENTS WHO PAID EXTRA
A4: 3 | B4: ARADHYA SONI | C4: 8-D | D4: {=TEXT(Table26[[#This Row],[Date]],"MMMM")} -> July | E4: 500 | F4: Ol | G4: 3 | H4: 46230 | I4: {=IFERROR(INDEX('ALL STUDENTS'!$A:$A, MATCH(1, ('ALL STUDENTS'!$B:$B = B4) * ('ALL STUDENTS'!$C:$C = C4), 0)), "NOT FOUND")} -> 8 | J4: =IF(Table26[[#This Row],[Fee]]>500,Table26[[#This Row],[Fee]],"")
A5: 4 | B5: PALAK RAJ | C5: 6-F | D5: {=TEXT(Table26[[#This Row],[Date]],"MMMM")} -> July | E5: 500 | F5: Ol | G5: 4 | H5: 46228 | I5: {=IFERROR(INDEX('ALL STUDENTS'!$A:$A, MATCH(1, ('ALL STUDENTS'!$B:$B = B5) * ('ALL STUDENTS'!$C:$C = C5), 0)), "NOT FOUND")} -> 717 | J5: =IF(Table26[[#This Row],[Fee]]>500,Table26[[#This Row],[Fee]],"") | L5: CLASS | M5: {=_xlfn.UNIQUE(_xlfn._xlws.FILTER(B:B,E:E>500,"NEXTRA PAYMENT"))} -> Name | N5: TOTAL PAID | O5: FEES
A6: 5 | B6: VIVAN SAHU | C6: 4-D | D6: {=TEXT(Table26[[#This Row],[Date]],"MMMM")} -> July | E6: 500 | F6: Ol | G6: 5 | H6: 46228 | I6: {=IFERROR(INDEX('ALL STUDENTS'!$A:$A, MATCH(1, ('ALL STUDENTS'!$B:$B = B6) * ('ALL STUDENTS'!$C:$C = C6), 0)), "NOT FOUND")} -> 2490 | J6: =IF(Table26[[#This Row],[Fee]]>500,Table26[[#This Row],[Fee]],"") | L6: =_xlfn.XLOOKUP(M6,B:B,C:C,"") -> 3-B | M6: ARYA CHOUBEY | N6: =SUMIF(B:B,M6,E:E) -> 4500 | O6: =N6-1500 -> 3000
A7: 6 | B7: RISHITA DESHMUKH | C7: 6-B | D7: {=TEXT(Table26[[#This Row],[Date]],"MMMM")} -> July | E7: 500 | F7: Ol | G7: 6 | H7: 46228 | I7: {=IFERROR(INDEX('ALL STUDENTS'!$A:$A, MATCH(1, ('ALL STUDENTS'!$B:$B = B7) * ('ALL STUDENTS'!$C:$C = C7), 0)), "NOT FOUND")} -> 746 | J7: =IF(Table26[[#This Row],[Fee]]>500,Table26[[#This Row],[Fee]],"") | L7: =_xlfn.XLOOKUP(M7,B:B,C:C,"") -> 3-F | M7: HIMAKSHI PANDRE | N7: =SUMIF(B:B,M7,E:E) -> 4500 | O7: =N7-1500 -> 3000
A8: 7 | B8: RISHITA DESHMUKH | C8: 6-B | D8: {=TEXT(Table26[[#This Row],[Date]],"MMMM")} -> July | E8: 500 | F8: Ol | G8: 7 | H8: 46228 | I8: {=IFERROR(INDEX('ALL STUDENTS'!$A:$A, MATCH(1, ('ALL STUDENTS'!$B:$B = B8) * ('ALL STUDENTS'!$C:$C = C8), 0)), "NOT FOUND")} -> 746 | J8: =IF(Table26[[#This Row],[Fee]]>500,Table26[[#This Row],[Fee]],"")
A9: 8 | B9: RISHITA DESHMUKH | C9: 6-B | D9: {=TEXT(Table26[[#This Row],[Date]],"MMMM")} -> July | E9: 500 | F9: Ol | G9: 8 | H9: 46228 | I9: {=IFERROR(INDEX('ALL STUDENTS'!$A:$A, MATCH(1, ('ALL STUDENTS'!$B:$B = B9) * ('ALL STUDENTS'!$C:$C = C9), 0)), "NOT FOUND")} -> 746 | J9: =IF(Table26[[#This Row],[Fee]]>500,Table26[[#This Row],[Fee]],"")
A10: 9 | B10: VIVAAN KAURAV | C10: 7-A | D10: {=TEXT(Table26[[#This Row],[Date]],"MMMM")} -> July | E10: 500 | F10: Ol | G10: 9 | H10: 46228 | I10: {=IFERROR(INDEX('ALL STUDENTS'!$A:$A, MATCH(1, ('ALL STUDENTS'!$B:$B = B10) * ('ALL STUDENTS'!$C:$C = C10), 0)), "NOT FOUND")} -> 265 | J10: =IF(Table26[[#This Row],[Fee]]>500,Table26[[#This Row],[Fee]],"")
A11: 10 | B11: VIVAAN KAURAV | C11: 7-A | D11: {=TEXT(Table26[[#This Row],[Date]],"MMMM")} -> July | E11: 500 | F11: Ol | G11: 10 | H11: 46228 | I11: {=IFERROR(INDEX('ALL STUDENTS'!$A:$A, MATCH(1, ('ALL STUDENTS'!$B:$B = B11) * ('ALL STUDENTS'!$C:$C = C11), 0)), "NOT FOUND")} -> 265 | J11: =IF(Table26[[#This Row],[Fee]]>500,Table26[[#This Row],[Fee]],"")
A12: 11 | B12: VIVAAN KAURAV | C12: 7-A | D12: {=TEXT(Table26[[#This Row],[Date]],"MMMM")} -> July | E12: 500 | F12: Ol | G12: 11 | H12: 46228 | I12: {=IFERROR(INDEX('ALL STUDENTS'!$A:$A, MATCH(1, ('ALL STUDENTS'!$B:$B = B12) * ('ALL STUDENTS'!$C:$C = C12), 0)), "NOT FOUND")} -> 265 | J12: =IF(Table26[[#This Row],[Fee]]>500,Table26[[#This Row],[Fee]],"")
A13: 12 | B13: PRATISHTHA PAWAR | C13: 8-B | D13: {=TEXT(Table26[[#This Row],[Date]],"MMMM")} -> July | E13: 500 | F13: Ol | G13: 12 | H13: 46228 | I13: {=IFERROR(INDEX('ALL STUDENTS'!$A:$A, MATCH(1, ('ALL STUDENTS'!$B:$B = B13) * ('ALL STUDENTS'!$C:$C = C13), 0)), "NOT FOUND")} -> 96 | J13: =IF(Table26[[#This Row],[Fee]]>500,Table26[[#This Row],[Fee]],"")
A14: 13 | B14: DAKSH SAINI | C14: 7-A | D14: {=TEXT(Table26[[#This Row],[Date]],"MMMM")} -> July | E14: 500 | F14: Ol | G14: 13 | H14: 46228 | I14: {=IFERROR(INDEX('ALL STUDENTS'!$A:$A, MATCH(1, ('ALL STUDENTS'!$B:$B = B14) * ('ALL STUDENTS'!$C:$C = C14), 0)), "NOT FOUND")} -> 246 | J14: =IF(Table26[[#This Row],[Fee]]>500,Table26[[#This Row],[Fee]],"") | L14: CURRENT TOTAL | M14: =SUM(E:E) -> 728500
A15: 14 | B15: SIDAK SINGH ANAND | C15: 8-G | D15: {=TEXT(Table26[[#This Row],[Date]],"MMMM")} -> July | E15: 500 | F15: Ol | G15: 14 | H15: 46226 | I15: {=IFERROR(INDEX('ALL STUDENTS'!$A:$A, MATCH(1, ('ALL STUDENTS'!$B:$B = B15) * ('ALL STUDENTS'!$C:$C = C15), 0)), "NOT FOUND")} -> 228 | J15: =IF(Table26[[#This Row],[Fee]]>500,Table26[[#This Row],[Fee]],"") | L15: TOTAL EXTRA PAID | M15: =SUM(O6:O12) -> 6000
A16: 15 | B16: AASHI CHOUBEY | C16: 7-E | D16: {=TEXT(Table26[[#This Row],[Date]],"MMMM")} -> July | E16: 500 | F16: Ol | G16: 15 | H16: 46227 | I16: {=IFERROR(INDEX('ALL STUDENTS'!$A:$A, MATCH(1, ('ALL STUDENTS'!$B:$B = B16) * ('ALL STUDENTS'!$C:$C = C16), 0)), "NOT FOUND")} -> 390 | J16: =IF(Table26[[#This Row],[Fee]]>500,Table26[[#This Row],[Fee]],"") | L16: TOTAL COLLECTION | M16: =M14-M15 -> 722500
A17: 16 | B17: AASHI CHOUBEY | C17: 7-E | D17: {=TEXT(Table26[[#This Row],[Date]],"MMMM")} -> July | E17: 500 | F17: Ol | G17: 16 | H17: 46227 | I17: {=IFERROR(INDEX('ALL STUDENTS'!$A:$A, MATCH(1, ('ALL STUDENTS'!$B:$B = B17) * ('ALL STUDENTS'!$C:$C = C17), 0)), "NOT FOUND")} -> 390 | J17: =IF(Table26[[#This Row],[Fee]]>500,Table26[[#This Row],[Fee]],"")
A18: 17 | B18: AASHI CHOUBEY | C18: 7-E | D18: {=TEXT(Table26[[#This Row],[Date]],"MMMM")} -> July | E18: 500 | F18: Ol | G18: 17 | H18: 46227 | I18: {=IFERROR(INDEX('ALL STUDENTS'!$A:$A, MATCH(1, ('ALL STUDENTS'!$B:$B = B18) * ('ALL STUDENTS'!$C:$C = C18), 0)), "NOT FOUND")} -> 390 | J18: =IF(Table26[[#This Row],[Fee]]>500,Table26[[#This Row],[Fee]],"")
A19: 18 | B19: SARTHAK KUMAR BHAGAT | C19: 8-C | D19: {=TEXT(Table26[[#This Row],[Date]],"MMMM")} -> July | E19: 500 | F19: Ol | G19: 18 | H19: 46225 | I19: {=IFERROR(INDEX('ALL STUDENTS'!$A:$A, MATCH(1, ('ALL STUDENTS'!$B:$B = B19) * ('ALL STUDENTS'!$C:$C = C19), 0)), "NOT FOUND")} -> 121 | J19: =IF(Table26[[#This Row],[Fee]]>500,Table26[[#This Row],[Fee]],"")
A20: 19 | B20: SARTHAK KUMAR BHAGAT | C20: 8-C | D20: {=TEXT(Table26[[#This Row],[Date]],"MMMM")} -> July | E20: 500 | F20: Ol | G20: 19 | H20: 46225 | I20: {=IFERROR(INDEX('ALL STUDENTS'!$A:$A, MATCH(1, ('ALL STUDENTS'!$B:$B = B20) * ('ALL STUDENTS'!$C:$C = C20), 0)), "NOT FOUND")} -> 121 | J20: =IF(Table26[[#This Row],[Fee]]>500,Table26[[#This Row],[Fee]],"")
A21: 20 | B21: SARTHAK KUMAR BHAGAT | C21: 8-C | D21: {=TEXT(Table26[[#This Row],[Date]],"MMMM")} -> July | E21: 500 | F21: Ol | G21: 20 | H21: 46225 | I21: {=IFERROR(INDEX('ALL STUDENTS'!$A:$A, MATCH(1, ('ALL STUDENTS'!$B:$B = B21) * ('ALL STUDENTS'!$C:$C = C21), 0)), "NOT FOUND")} -> 121 | J21: =IF(Table26[[#This Row],[Fee]]>500,Table26[[#This Row],[Fee]],"")
A22: 21 | B22: ABHIRAJ GHOSH | C22: 6-D | D22: {=TEXT(Table26[[#This Row],[Date]],"MMMM")} -> July | E22: 500 | F22: Ol | G22: 21 | H22: 46226 | I22: {=IFERROR(INDEX('ALL STUDENTS'!$A:$A, MATCH(1, ('ALL STUDENTS'!$B:$B = B22) * ('ALL STUDENTS'!$C:$C = C22), 0)), "NOT FOUND")} -> 629 | J22: =IF(Table26[[#This Row],[Fee]]>500,Table26[[#This Row],[Fee]],"")
A23: 22 | B23: ABHIRAJ GHOSH | C23: 6-D | D23: {=TEXT(Table26[[#This Row],[Date]],"MMMM")} -> July | E23: 500 | F23: Ol | G23: 22 | H23: 46226 | I23: {=IFERROR(INDEX('ALL STUDENTS'!$A:$A, MATCH(1, ('ALL STUDENTS'!$B:$B = B23) * ('ALL STUDENTS'!$C:$C = C23), 0)), "NOT FOUND")} -> 629 | J23: =IF(Table26[[#This Row],[Fee]]>500,Table26[[#This Row],[Fee]],"")
A24: 23 | B24: ABHIRAJ GHOSH | C24: 6-D | D24: {=TEXT(Table26[[#This Row],[Date]],"MMMM")} -> July | E24: 500 | F24: Ol | G24: 23 | H24: 46226 | I24: {=IFERROR(INDEX('ALL STUDENTS'!$A:$A, MATCH(1, ('ALL STUDENTS'!$B:$B = B24) * ('ALL STUDENTS'!$C:$C = C24), 0)), "NOT FOUND")} -> 629 | J24: =IF(Table26[[#This Row],[Fee]]>500,Table26[[#This Row],[Fee]],"")
A25: 24 | B25: TUBHYAM JAIN | C25: 5-B | D25: {=TEXT(Table26[[#This Row],[Date]],"MMMM")} -> July | E25: 500 | F25: Ol | G25: 24 | H25: 46225 | I25: {=IFERROR(INDEX('ALL STUDENTS'!$A:$A, MATCH(1, ('ALL STUDENTS'!$B:$B = B25) * ('ALL STUDENTS'!$C:$C = C25), 0)), "NOT FOUND")} -> 825 | J25: =IF(Table26[[#This Row],[Fee]]>500,Table26[[#This Row],[Fee]],"")
A26: 25 | B26: RITVI JAIN | C26: 4-E | D26: {=TEXT(Table26[[#This Row],[Date]],"MMMM")} -> July | E26: 500 | F26: Ol | G26: 25 | H26: 46230 | I26: {=IFERROR(INDEX('ALL STUDENTS'!$A:$A, MATCH(1, ('ALL STUDENTS'!$B:$B = B26) * ('ALL STUDENTS'!$C:$C = C26), 0)), "NOT FOUND")} -> 2515 | J26: =IF(Table26[[#This Row],[Fee]]>500,Table26[[#This Row],[Fee]],"")
A27: 26 | B27: SARTHAK VISHWAY | C27: 5-E | D27: {=TEXT(Table26[[#This Row],[Date]],"MMMM")} -> July | E27: 500 | F27: Ol | G27: 26 | H27: 46231 | I27: {=IFERROR(INDEX('ALL STUDENTS'!$A:$A, MATCH(1, ('ALL STUDENTS'!$B:$B = B27) * ('ALL STUDENTS'!$C:$C = C27), 0)), "NOT FOUND")} -> 938 | J27: =IF(Table26[[#This Row],[Fee]]>500,Table26[[#This Row],[Fee]],"")
A28: 27 | B28: SARTHAK VISHWAY | C28: 5-E | D28: {=TEXT(Table26[[#This Row],[Date]],"MMMM")} -> July | E28: 500 | F28: Ol | G28: 27 | H28: 46231 | I28: {=IFERROR(INDEX('ALL STUDENTS'!$A:$A, MATCH(1, ('ALL STUDENTS'!$B:$B = B28) * ('ALL STUDENTS'!$C:$C = C28), 0)), "NOT FOUND")} -> 938 | J28: =IF(Table26[[#This Row],[Fee]]>500,Table26[[#This Row],[Fee]],"")
... A1163: 1162 | B1163: RITIKA SAHU | C1163: 5-G | D1163: {=TEXT(Table26[[#This Row],[Date]],"MMMM")} -> September | E1163: 500 | F1163: Ol | G1163: 1163 | H1163: 46276 | I1163: {=IFERROR(INDEX('ALL STUDENTS'!$A:$A, MATCH(1, ('ALL STUDENTS'!$B:$B = B1163) * ('ALL STUDENTS'!$C:$C = C1163), 0)), "NOT FOUND")} -> 1004 | J1163: =IF(Table26[[#This Row],[Fee]]>500,Table26[[#This Row],[Fee]],"")
A1164: 1163 | B1164: SARTHAK SATPUTE | C1164: 4-F | D1164: {=TEXT(Table26[[#This Row],[Date]],"MMMM")} -> August | E1164: 500 | F1164: Ol | G1164: 1164 | H1164: 46243 | I1164: {=IFERROR(INDEX('ALL STUDENTS'!$A:$A, MATCH(1, ('ALL STUDENTS'!$B:$B = B1164) * ('ALL STUDENTS'!$C:$C = C1164), 0)), "NOT FOUND")} -> 2561
A1165: 1164 | B1165: SARTHAK SATPUTE | C1165: 4-F | D1165: {=TEXT(Table26[[#This Row],[Date]],"MMMM")} -> August | E1165: 500 | F1165: Ol | G1165: 1165 | H1165: 46243 | I1165: {=IFERROR(INDEX('ALL STUDENTS'!$A:$A, MATCH(1, ('ALL STUDENTS'!$B:$B = B1165) * ('ALL STUDENTS'!$C:$C = C1165), 0)), "NOT FOUND")} -> 2561
A1166: 1165 | B1166: SARTHAK SATPUTE | C1166: 4-F | D1166: {=TEXT(Table26[[#This Row],[Date]],"MMMM")} -> August | E1166: 500 | F1166: Ol | G1166: 1166 | H1166: 46243 | I1166: {=IFERROR(INDEX('ALL STUDENTS'!$A:$A, MATCH(1, ('ALL STUDENTS'!$B:$B = B1166) * ('ALL STUDENTS'!$C:$C = C1166), 0)), "NOT FOUND")} -> 2561
A1167: 1166 | B1167: NIKHIL PATEL | C1167: 2-C | D1167: {=TEXT(Table26[[#This Row],[Date]],"MMMM")} -> September | E1167: 500 | F1167: Ol | G1167: 1167 | H1167: 46277 | I1167: {=IFERROR(INDEX('ALL STUDENTS'!$A:$A, MATCH(1, ('ALL STUDENTS'!$B:$B = B1167) * ('ALL STUDENTS'!$C:$C = C1167), 0)), "NOT FOUND")} -> 1890 | J1167: =IF(Table26[[#This Row],[Fee]]>500,Table26[[#This Row],[Fee]],"")
A1168: 1167 | B1168: ARUNIMA S BAGHEL | C1168: UKG-F | D1168: {=TEXT(Table26[[#This Row],[Date]],"MMMM")} -> September | E1168: 500 | F1168: Ol | G1168: 1168 | H1168: 46276 | I1168: {=IFERROR(INDEX('ALL STUDENTS'!$A:$A, MATCH(1, ('ALL STUDENTS'!$B:$B = B1168) * ('ALL STUDENTS'!$C:$C = C1168), 0)), "NOT FOUND")} -> 3180 | J1168: =IF(Table26[[#This Row],[Fee]]>500,Table26[[#This Row],[Fee]],"")
A1169: 1168 | B1169: KANISHKA GUPTA | C1169: UKG-C | D1169: {=TEXT(Table26[[#This Row],[Date]],"MMMM")} -> September | E1169: 500 | F1169: Ol | G1169: 1169 | H1169: 46275 | I1169: {=IFERROR(INDEX('ALL STUDENTS'!$A:$A, MATCH(1, ('ALL STUDENTS'!$B:$B = B1169) * ('ALL STUDENTS'!$C:$C = C1169), 0)), "NOT FOUND")} -> 3080 | J1169: =IF(Table26[[#This Row],[Fee]]>500,Table26[[#This Row],[Fee]],"")
A1170: 1169 | B1170: KEVIN JOHN | C1170: UKG-D | D1170: {=TEXT(Table26[[#This Row],[Date]],"MMMM")} -> September | E1170: 500 | F1170: Ol | G1170: 1170 | H1170: 46280 | I1170: {=IFERROR(INDEX('ALL STUDENTS'!$A:$A, MATCH(1, ('ALL STUDENTS'!$B:$B = B1170) * ('ALL STUDENTS'!$C:$C = C1170), 0)), "NOT FOUND")} -> 3117 | J1170: =IF(Table26[[#This Row],[Fee]]>500,Table26[[#This Row],[Fee]],"")
A1171: 1170 | B1171: KEVIN JOHN | C1171: UKG-D | D1171: {=TEXT(Table26[[#This Row],[Date]],"MMMM")} -> September | E1171: 500 | F1171: Ol | G1171: 1171 | H1171: 46280 | I1171: {=IFERROR(INDEX('ALL STUDENTS'!$A:$A, MATCH(1, ('ALL STUDENTS'!$B:$B = B1171) * ('ALL STUDENTS'!$C:$C = C1171), 0)), "NOT FOUND")} -> 3117 | J1171: =IF(Table26[[#This Row],[Fee]]>500,Table26[[#This Row],[Fee]],"")
A1172: 1171 | B1172: KEVIN JOHN | C1172: UKG-D | D1172: {=TEXT(Table26[[#This Row],[Date]],"MMMM")} -> September | E1172: 500 | F1172: Ol | G1172: 1172 | H1172: 46280 | I1172: {=IFERROR(INDEX('ALL STUDENTS'!$A:$A, MATCH(1, ('ALL STUDENTS'!$B:$B = B1172) * ('ALL STUDENTS'!$C:$C = C1172), 0)), "NOT FOUND")} -> 3117 | J1172: =IF(Table26[[#This Row],[Fee]]>500,Table26[[#This Row],[Fee]],"")
A1173: 1172 | B1173: AYANSH GUPTA | C1173: 9-G | D1173: {=TEXT(Table26[[#This Row],[Date]],"MMMM")} -> September | E1173: 500 | F1173: Ol | G1173: 1173 | H1173: 46277 | I1173: {=IFERROR(INDEX('ALL STUDENTS'!$A:$A, MATCH(1, ('ALL STUDENTS'!$B:$B = B1173) * ('ALL STUDENTS'!$C:$C = C1173), 0)), "NOT FOUND")} -> 1317 | J1173: =IF(Table26[[#This Row],[Fee]]>500,Table26[[#This Row],[Fee]],"")
A1174: 1173 | B1174: AYANSH GUPTA | C1174: 9-G | D1174: {=TEXT(Table26[[#This Row],[Date]],"MMMM")} -> September | E1174: 500 | F1174: Ol | G1174: 1174 | H1174: 46277 | I1174: {=IFERROR(INDEX('ALL STUDENTS'!$A:$A, MATCH(1, ('ALL STUDENTS'!$B:$B = B1174) * ('ALL STUDENTS'!$C:$C = C1174), 0)), "NOT FOUND")} -> 1317 | J1174: =IF(Table26[[#This Row],[Fee]]>500,Table26[[#This Row],[Fee]],"")
...

Sheet ALL STUDENTS
A1: BOOK No. | B1: Name | C1: Class | D1: INSTALLMENT | E1: 1 INSTALL | F1: 2 INSTALL | G1: 3 INSTALL
A2: 1 | B2: AADI SRISHA | C2: 8-D | D2: =COUNTIFS('Raw Entries'!B:B,Table4[[#This Row],[Name]],'Raw Entries'!I:I,Table4[[#This Row],[BOOK No.]]) -> 0 | E2: {=IF(OR(Table4[[#This Row],[INSTALLMENT]]=1,Table4[[#This Row],[INSTALLMENT]]=2,Table4[[#This Row],[INSTALLMENT]]=3),1,0)} -> 0 | F2: =IF(OR(Table4[[#This Row],[INSTALLMENT]]=2,Table4[[#This Row],[INSTALLMENT]]=3),2,0) -> 0 | G2: =IF(OR(Table4[[#This Row],[INSTALLMENT]]=3),3,0) -> 0
A3: 2 | B3: AARNA SHARMA | C3: 8-D | D3: =COUNTIFS('Raw Entries'!B:B,Table4[[#This Row],[Name]],'Raw Entries'!I:I,Table4[[#This Row],[BOOK No.]]) -> 0 | E3: {=IF(OR(Table4[[#This Row],[INSTALLMENT]]=1,Table4[[#This Row],[INSTALLMENT]]=2,Table4[[#This Row],[INSTALLMENT]]=3),1,0)} -> 0 | F3: =IF(OR(Table4[[#This Row],[INSTALLMENT]]=2,Table4[[#This Row],[INSTALLMENT]]=3),2,0) -> 0 | G3: =IF(OR(Table4[[#This Row],[INSTALLMENT]]=3),3,0) -> 0
A4: 3 | B4: AKSHAT SHARMA | C4: 8-D | D4: =COUNTIFS('Raw Entries'!B:B,Table4[[#This Row],[Name]],'Raw Entries'!I:I,Table4[[#This Row],[BOOK No.]]) -> 0 | E4: {=IF(OR(Table4[[#This Row],[INSTALLMENT]]=1,Table4[[#This Row],[INSTALLMENT]]=2,Table4[[#This Row],[INSTALLMENT]]=3),1,0)} -> 0 | F4: =IF(OR(Table4[[#This Row],[INSTALLMENT]]=2,Table4[[#This Row],[INSTALLMENT]]=3),2,0) -> 0 | G4: =IF(OR(Table4[[#This Row],[INSTALLMENT]]=3),3,0) -> 0
A5: 4 | B5: ANANYA SONI | C5: 8-D | D5: =COUNTIFS('Raw Entries'!B:B,Table4[[#This Row],[Name]],'Raw Entries'!I:I,Table4[[#This Row],[BOOK No.]]) -> 0 | E5: {=IF(OR(Table4[[#This Row],[INSTALLMENT]]=1,Table4[[#This Row],[INSTALLMENT]]=2,Table4[[#This Row],[INSTALLMENT]]=3),1,0)} -> 0 | F5: =IF(OR(Table4[[#This Row],[INSTALLMENT]]=2,Table4[[#This Row],[INSTALLMENT]]=3),2,0) -> 0 | G5: =IF(OR(Table4[[#This Row],[INSTALLMENT]]=3),3,0) -> 0
A6: 5 | B6: ANUSHA BHUSARI | C6: 8-D | D6: =COUNTIFS('Raw Entries'!B:B,Table4[[#This Row],[Name]],'Raw Entries'!I:I,Table4[[#This Row],[BOOK No.]]) -> 0 | E6: {=IF(OR(Table4[[#This Row],[INSTALLMENT]]=1,Table4[[#This Row],[INSTALLMENT]]=2,Table4[[#This Row],[INSTALLMENT]]=3),1,0)} -> 0 | F6: =IF(OR(Table4[[#This Row],[INSTALLMENT]]=2,Table4[[#This Row],[INSTALLMENT]]=3),2,0) -> 0 | G6: =IF(OR(Table4[[#This Row],[INSTALLMENT]]=3),3,0) -> 0
A7: 6 | B7: ANUSHREE BOSE | C7: 8-D | D7: =COUNTIFS('Raw Entries'!B:B,Table4[[#This Row],[Name]],'Raw Entries'!I:I,Table4[[#This Row],[BOOK No.]]) -> 0 | E7: {=IF(OR(Table4[[#This Row],[INSTALLMENT]]=1,Table4[[#This Row],[INSTALLMENT]]=2,Table4[[#This Row],[INSTALLMENT]]=3),1,0)} -> 0 | F7: =IF(OR(Table4[[#This Row],[INSTALLMENT]]=2,Table4[[#This Row],[INSTALLMENT]]=3),2,0) -> 0 | G7: =IF(OR(Table4[[#This Row],[INSTALLMENT]]=3),3,0) -> 0
A8: 7 | B8: ARADHAYA BAIRWAN | C8: 8-D | D8: =COUNTIFS('Raw Entries'!B:B,Table4[[#This Row],[Name]],'Raw Entries'!I:I,Table4[[#This Row],[BOOK No.]]) -> 0 | E8: {=IF(OR(Table4[[#This Row],[INSTALLMENT]]=1,Table4[[#This Row],[INSTALLMENT]]=2,Table4[[#This Row],[INSTALLMENT]]=3),1,0)} -> 0 | F8: =IF(OR(Table4[[#This Row],[INSTALLMENT]]=2,Table4[[#This Row],[INSTALLMENT]]=3),2,0) -> 0 | G8: =IF(OR(Table4[[#This Row],[INSTALLMENT]]=3),3,0) -> 0
A9: 8 | B9: ARADHYA SONI | C9: 8-D | D9: =COUNTIFS('Raw Entries'!B:B,Table4[[#This Row],[Name]],'Raw Entries'!I:I,Table4[[#This Row],[BOOK No.]]) -> 3 | E9: {=IF(OR(Table4[[#This Row],[INSTALLMENT]]=1,Table4[[#This Row],[INSTALLMENT]]=2,Table4[[#This Row],[INSTALLMENT]]=3),1,0)} -> 1 | F9: =IF(OR(Table4[[#This Row],[INSTALLMENT]]=2,Table4[[#This Row],[INSTALLMENT]]=3),2,0) -> 2 | G9: =IF(OR(Table4[[#This Row],[INSTALLMENT]]=3),3,0) -> 3
A10: 9 | B10: ARYAN KANOJIYA | C10: 8-D | D10: =COUNTIFS('Raw Entries'!B:B,Table4[[#This Row],[Name]],'Raw Entries'!I:I,Table4[[#This Row],[BOOK No.]]) -> 0 | E10: {=IF(OR(Table4[[#This Row],[INSTALLMENT]]=1,Table4[[#This Row],[INSTALLMENT]]=2,Table4[[#This Row],[INSTALLMENT]]=3),1,0)} -> 0 | F10: =IF(OR(Table4[[#This Row],[INSTALLMENT]]=2,Table4[[#This Row],[INSTALLMENT]]=3),2,0) -> 0 | G10: =IF(OR(Table4[[#This Row],[INSTALLMENT]]=3),3,0) -> 0
A11: 10 | B11: AVANTIKA SARATHE | C11: 8-D | D11: =COUNTIFS('Raw Entries'!B:B,Table4[[#This Row],[Name]],'Raw Entries'!I:I,Table4[[#This Row],[BOOK No.]]) -> 0 | E11: {=IF(OR(Table4[[#This Row],[INSTALLMENT]]=1,Table4[[#This Row],[INSTALLMENT]]=2,Table4[[#This Row],[INSTALLMENT]]=3),1,0)} -> 0 | F11: =IF(OR(Table4[[#This Row],[INSTALLMENT]]=2,Table4[[#This Row],[INSTALLMENT]]=3),2,0) -> 0 | G11: =IF(OR(Table4[[#This Row],[INSTALLMENT]]=3),3,0) -> 0
A12: 11 | B12: AVIRAJ SINGH THAKUR | C12: 8-D | D12: =COUNTIFS('Raw Entries'!B:B,Table4[[#This Row],[Name]],'Raw Entries'!I:I,Table4[[#This Row],[BOOK No.]]) -> 1 | E12: {=IF(OR(Table4[[#This Row],[INSTALLMENT]]=1,Table4[[#This Row],[INSTALLMENT]]=2,Table4[[#This Row],[INSTALLMENT]]=3),1,0)} -> 1 | F12: =IF(OR(Table4[[#This Row],[INSTALLMENT]]=2,Table4[[#This Row],[INSTALLMENT]]=3),2,0) -> 0 | G12: =IF(OR(Table4[[#This Row],[INSTALLMENT]]=3),3,0) -> 0
A13: 12 | B13: DHAIRYA SINGH PARIHAR | C13: 8-D | D13: =COUNTIFS('Raw Entries'!B:B,Table4[[#This Row],[Name]],'Raw Entries'!I:I,Table4[[#This Row],[BOOK No.]]) -> 0 | E13: {=IF(OR(Table4[[#This Row],[INSTALLMENT]]=1,Table4[[#This Row],[INSTALLMENT]]=2,Table4[[#This Row],[INSTALLMENT]]=3),1,0)} -> 0 | F13: =IF(OR(Table4[[#This Row],[INSTALLMENT]]=2,Table4[[#This Row],[INSTALLMENT]]=3),2,0) -> 0 | G13: =IF(OR(Table4[[#This Row],[INSTALLMENT]]=3),3,0) -> 0
... A2602: 3200 | B2602: DISHANT DHURWEY | C2602: UKG-F | D2602: =COUNTIFS('Raw Entries'!B:B,Table4[[#This Row],[Name]],'Raw Entries'!I:I,Table4[[#This Row],[BOOK No.]]) -> 0 | E2602: {=IF(OR(Table4[[#This Row],[INSTALLMENT]]=1,Table4[[#This Row],[INSTALLMENT]]=2,Table4[[#This Row],[INSTALLMENT]]=3),1,0)} -> 0 | F2602: =IF(OR(Table4[[#This Row],[INSTALLMENT]]=2,Table4[[#This Row],[INSTALLMENT]]=3),2,0) -> 0 | G2602: =IF(OR(Table4[[#This Row],[INSTALLMENT]]=3),3,0) -> 0
